Workbook
Name All_Vars: MODEL_Run!$F$5:$F$10,MODEL_Run!$F$13:$F$66,MODEL_Run!$F$69:$F$122,MODEL_Run!$F$125:$F$259,MODEL_Run!$F$262:$F$279,MODEL_Run!$F$282:$F$284
Name Cameras_LHS: Constraints_flat!$G$44
Name Cameras_RHS: Constraints_flat!$H$44
Name Capacity_LHS: Constraints_flat!$I$38:$I$43
Name Capacity_RHS: Constraints_flat!$J$38:$J$43
Name Demand_LHS: Constraints_flat!$I$21:$I$36
Name Demand_RHS: Constraints_flat!$J$21:$J$36
Name E_range: MODEL_Run!$F$5:$F$10
Name Flow_LHS: Constraints_flat!$I$2:$I$19
Name Flow_RHS: Constraints_flat!$J$2:$J$19
Name S_range: MODEL_Run!$F$125:$F$259
Name X_range: MODEL_Run!$F$13:$F$66
Name X_range1: Decisions_struct!$1:$55,Decisions_struct!$272:$1048576
Name XOT_range: MODEL_Run!$F$69:$F$122
Name Y_range: MODEL_Run!$F$262:$F$279
Name YPT_range: MODEL_Run!$F$282:$F$284
Name Z_range: Objective!$E$3

Sheet Solver_ReadMe
A1: Use these names in Solver to avoid selection errors:
A3: Objective (min): Decisions_struct!$B$1 (this mirrors Objective!E3)
A5: By Changing: X_range, XOT_range, S_range, Y_range, YPT_range, E_range
A7: Constraints:
A8: Flow_LHS <= Flow_RHS
A9: Demand_LHS = Demand_RHS
A10: Capacity_LHS <= Capacity_RHS
A11: Cameras_LHS <= Cameras_RHS
A12: Premium_Total <= Premium_Budget (optional)
A14: Method: Simplex LP; Options: Assume Linear Model; Make Unconstrained Vars Non-Negative
A16: Tip: If a name doesn't paste with F3 (Paste Name), Formulas → Name Manager to confirm it exists.

Sheet Parameters
A1: Index Sets (for reference) | H1: Helper: (p,w) -> W^S, W^E
A2: Plants (p) | B2: K=Kaohsiung, C=Chennai, G=Guadalajara | H2: p | I2: w | J2: W^S | K2: W^E
A3: Products (i) | B3: P=Phone, T=Tablet, L=Laptop | H3: K | I3: 45 | J3: =C38 -> 0 | K3: =D38 -> 0
A4: Weeks (w) | B4: 45=Nov10, 46=Nov17 | H4: K | I4: 46 | J4: =C39 -> 0 | K4: =D39 -> 0
A5: Customers (c) | B5: Orange, Enterprise, Amazon, BestBuy, Target | H5: C | I5: 45 | J5: =C40 -> 0 | K5: =D40 -> 0
H6: C | I6: 46 | J6: =C41 -> 0 | K6: =D41 -> 0
H7: G | I7: 45 | J7: =C42 -> 0 | K7: =D42 -> 0
A8: Base Weekly Capacity Cap_p | H8: G | I8: 46 | J8: =C43 -> 0 | K8: =D43 -> 0
A9: Plant | B9: Cap_p (units/week)
A10: Kaohsiung (TW) | B10: 52500
A11: Chennai (IN) | B11: 80000
A12: Guadalajara (MX) | B12: 40000
A14: Shipping Costs
A15: Plant | B15: S^S_p ($/unit) | C15: S^E_p ($/unit) | D15: Premium (S^E - S^S)
A16: Kaohsiung (TW) | B16: 15 | C16: 60 | D16: 45
A17: Chennai (IN) | B17: 16 | C17: 65 | D17: 49
A18: Guadalajara (MX) | B18: 5 | C18: 15 | D18: 10
A20: Transit Days
A21: Plant | B21: D^S_p (days) | C21: D^E_p (days)
A22: Kaohsiung (TW) | B22: 18 | C22: 3
A23: Chennai (IN) | B23: 20 | C23: 4
A24: Guadalajara (MX) | B24: 3 | C24: 1
A26: Resource Factors r_i
A27: Product | B27: r_i
A28: P | B28: 1
A29: T | B29: 1.5
A30: L | B30: 2
A32: Emergency Budget B (premiums only)
A33: B ($)
B34: 15000000
A36: Delivery Window Parameters
A37: (Enter) A^S_{p,w} days | B37: (Enter) A^E_{p,w} days | C37: W^S = A^S/7 | D37: W^E = A^E/7 | F37: Provide A^S and A^E (days) for each (p,w).
C38: =A38/7 -> 0 | D38: =B38/7 -> 0 | F38: p=K, w=45
C39: =A39/7 -> 0 | D39: =B39/7 -> 0 | F39: p=K, w=46
C40: =A40/7 -> 0 | D40: =B40/7 -> 0 | F40: p=C, w=45
C41: =A41/7 -> 0 | D41: =B41/7 -> 0 | F41: p=C, w=46
C42: =A42/7 -> 0 | D42: =B42/7 -> 0 | F42: p=G, w=45
C43: =A43/7 -> 0 | D43: =B43/7 -> 0 | F43: p=G, w=46
A46: Camera Modules
A47: Total Cameras Available (all plants) | B47: (enter total, e.g., 455000)
...

Sheet Demand
A1: Enter due-week demand d_{c,i} and due week w_c per customer
A2: Customer | B2: Product | C2: d_{c,i} (units) | D2: Due Week (w_c)
A3: Orange | B3: P | C3: 60000 | D3: 45
A4: Orange | B4: T | C4: 20000 | D4: 45
A5: Orange | B5: L | C5: 18000 | D5: 45
A6: Enterprise | B6: P | C6: 10000 | D6: 45
A7: Enterprise | B7: T | C7: 5000 | D7: 45
A8: Enterprise | B8: L | C8: 30000 | D8: 45
A9: Amazon | B9: P | C9: 80000 | D9: 46
A10: Amazon | B10: T | C10: 40000 | D10: 46
A11: Amazon | B11: L | C11: 25000 | D11: 46
A12: BestBuy | B12: P | C12: 50000 | D12: 46
A13: BestBuy | B13: T | C13: 30000 | D13: 46
A14: BestBuy | B14: L | C14: 15000 | D14: 46
... A17: Target | B17: L | C17: 10000 | D17: 46

Sheet Production_Costs
A1: Unit production costs C_{p,i} ($/unit)
A2: Plant | B2: P | C2: T | D2: L
A3: Kaohsiung (TW) | B3: 390 | C3: 585 | D3: 750
A4: Chennai (IN) | B4: 427 | C4: 640 | D4: 790
A5: Guadalajara (MX) | B5: 466 | C5: 699 | D5: 814

Sheet Decisions
A1: Decision Variables (Solver will change these cells) | F1: Named Ranges for Solver
F2: Name | G2: Range
A3: X_{p,i,w} (regular units)
A4: p=K, i=P, w=45 | F4: X_range | G4: =Decisions!B4:B21 -> 0
A5: p=K, i=P, w=46 | F5: XOT_range | G5: =Decisions!B24:B41 -> #VALUE!
A6: p=K, i=T, w=45 | F6: Y_range | G6: =Decisions!B44:B49 -> #VALUE!
A7: p=K, i=T, w=46 | F7: E_range | G7: =Decisions!B52:B57 -> #VALUE!
A8: p=K, i=L, w=45 | F8: S_range | G8: =Decisions!B60:B149 -> #VALUE!
A9: p=K, i=L, w=46 | F9: Z_range | G9: =Decisions!B152:B166 -> #VALUE!
A10: p=C, i=P, w=45 | F10: YPT_range | G10: =Decisions!B169:B198 -> #VALUE!
A11: p=C, i=P, w=46
A12: p=C, i=T, w=45
A13: p=C, i=T, w=46
A14: p=C, i=L, w=45
A15: p=C, i=L, w=46
A16: p=G, i=P, w=45
A17: p=G, i=P, w=46
A18: p=G, i=T, w=45
A19: p=G, i=T, w=46
A20: p=G, i=L, w=45
A21: p=G, i=L, w=46
A23: X^OT_{p,i,w} (overtime units)
... A198: c=Target, i=L, w=46

Sheet Derived
A1: Derived quantities and objective components
A2: Plant | B2: Week | C2: Q_{p,w} | D2: E_{p,w} | E2: Cap_p | F2: W^S | G2: W^E
A3: Kaohsiung (TW) | B3: 45 | C3: =Decisions!B4+Decisions!B24+Decisions!B6+Decisions!B26+Decisions!B8+Decisions!B28 -> 0 | D3: =Decisions!B52 -> 0 | E3: 52500 | F3: =INDEX(Parameters!$J:$J, MATCH(1, (Parameters!$H:$H="K")*(Parameters!$I:$I=45),0)) -> #N/A | G3: =INDEX(Parameters!$K:$K, MATCH(1, (Parameters!$H:$H="K")*(Parameters!$I:$I=45),0)) -> #N/A
A4: Kaohsiung (TW) | B4: 46 | C4: =Decisions!B5+Decisions!B25+Decisions!B7+Decisions!B27+Decisions!B9+Decisions!B29 -> 0 | D4: =Decisions!B53 -> 0 | E4: 52500 | F4: =INDEX(Parameters!$J:$J, MATCH(1, (Parameters!$H:$H="K")*(Parameters!$I:$I=46),0)) -> #N/A | G4: =INDEX(Parameters!$K:$K, MATCH(1, (Parameters!$H:$H="K")*(Parameters!$I:$I=46),0)) -> #N/A
A5: Chennai (IN) | B5: 45 | C5: =Decisions!B10+Decisions!B30+Decisions!B12+Decisions!B32+Decisions!B14+Decisions!B34 -> 0 | D5: =Decisions!B54 -> 0 | E5: 80000 | F5: =INDEX(Parameters!$J:$J, MATCH(1, (Parameters!$H:$H="C")*(Parameters!$I:$I=45),0)) -> #N/A | G5: =INDEX(Parameters!$K:$K, MATCH(1, (Parameters!$H:$H="C")*(Parameters!$I:$I=45),0)) -> #N/A
A6: Chennai (IN) | B6: 46 | C6: =Decisions!B11+Decisions!B31+Decisions!B13+Decisions!B33+Decisions!B15+Decisions!B35 -> 0 | D6: =Decisions!B55 -> 0 | E6: 80000 | F6: =INDEX(Parameters!$J:$J, MATCH(1, (Parameters!$H:$H="C")*(Parameters!$I:$I=46),0)) -> #N/A | G6: =INDEX(Parameters!$K:$K, MATCH(1, (Parameters!$H:$H="C")*(Parameters!$I:$I=46),0)) -> #N/A
A7: Guadalajara (MX) | B7: 45 | C7: =Decisions!B16+Decisions!B36+Decisions!B18+Decisions!B38+Decisions!B20+Decisions!B40 -> 0 | D7: =Decisions!B56 -> 0 | E7: 40000 | F7: =INDEX(Parameters!$J:$J, MATCH(1, (Parameters!$H:$H="G")*(Parameters!$I:$I=45),0)) -> #N/A | G7: =INDEX(Parameters!$K:$K, MATCH(1, (Parameters!$H:$H="G")*(Parameters!$I:$I=45),0)) -> #N/A
A8: Guadalajara (MX) | B8: 46 | C8: =Decisions!B17+Decisions!B37+Decisions!B19+Decisions!B39+Decisions!B21+Decisions!B41 -> 0 | D8: =Decisions!B57 -> 0 | E8: 40000 | F8: =INDEX(Parameters!$J:$J, MATCH(1, (Parameters!$H:$H="G")*(Parameters!$I:$I=46),0)) -> #N/A | G8: =INDEX(Parameters!$K:$K, MATCH(1, (Parameters!$H:$H="G")*(Parameters!$I:$I=46),0)) -> #N/A

Sheet Constraints
A1: Constraint LHS and RHS
A3: Flow balance: sum_c S_{c,i,w,p} <= X+XOT
A4: p | B4: i | C4: w | D4: LHS (sum S) | E4: RHS (X+XOT)
A5: K | B5: P | C5: 45 | D5: =Decisions!B60+Decisions!B78+Decisions!B96+Decisions!B114+Decisions!B132 -> 0 | E5: =Decisions!B4+Decisions!B24 -> 0
A6: K | B6: P | C6: 46 | D6: =Decisions!B63+Decisions!B81+Decisions!B99+Decisions!B117+Decisions!B135 -> 0 | E6: =Decisions!B5+Decisions!B25 -> 0
A7: K | B7: T | C7: 45 | D7: =Decisions!B66+Decisions!B84+Decisions!B102+Decisions!B120+Decisions!B138 -> 0 | E7: =Decisions!B6+Decisions!B26 -> 0
A8: K | B8: T | C8: 46 | D8: =Decisions!B69+Decisions!B87+Decisions!B105+Decisions!B123+Decisions!B141 -> 0 | E8: =Decisions!B7+Decisions!B27 -> 0
A9: K | B9: L | C9: 45 | D9: =Decisions!B72+Decisions!B90+Decisions!B108+Decisions!B126+Decisions!B144 -> 0 | E9: =Decisions!B8+Decisions!B28 -> 0
A10: K | B10: L | C10: 46 | D10: =Decisions!B75+Decisions!B93+Decisions!B111+Decisions!B129+Decisions!B147 -> 0 | E10: =Decisions!B9+Decisions!B29 -> 0
A11: C | B11: P | C11: 45 | D11: =Decisions!B61+Decisions!B79+Decisions!B97+Decisions!B115+Decisions!B133 -> 0 | E11: =Decisions!B10+Decisions!B30 -> 0
A12: C | B12: P | C12: 46 | D12: =Decisions!B64+Decisions!B82+Decisions!B100+Decisions!B118+Decisions!B136 -> 0 | E12: =Decisions!B11+Decisions!B31 -> 0
A13: C | B13: T | C13: 45 | D13: =Decisions!B67+Decisions!B85+Decisions!B103+Decisions!B121+Decisions!B139 -> 0 | E13: =Decisions!B12+Decisions!B32 -> 0
A14: C | B14: T | C14: 46 | D14: =Decisions!B70+Decisions!B88+Decisions!B106+Decisions!B124+Decisions!B142 -> 0 | E14: =Decisions!B13+Decisions!B33 -> 0
A15: C | B15: L | C15: 45 | D15: =Decisions!B73+Decisions!B91+Decisions!B109+Decisions!B127+Decisions!B145 -> 0 | E15: =Decisions!B14+Decisions!B34 -> 0
A16: C | B16: L | C16: 46 | D16: =Decisions!B76+Decisions!B94+Decisions!B112+Decisions!B130+Decisions!B148 -> 0 | E16: =Decisions!B15+Decisions!B35 -> 0
A17: G | B17: P | C17: 45 | D17: =Decisions!B62+Decisions!B80+Decisions!B98+Decisions!B116+Decisions!B134 -> 0 | E17: =Decisions!B16+Decisions!B36 -> 0
A18: G | B18: P | C18: 46 | D18: =Decisions!B65+Decisions!B83+Decisions!B101+Decisions!B119+Decisions!B137 -> 0 | E18: =Decisions!B17+Decisions!B37 -> 0
A19: G | B19: T | C19: 45 | D19: =Decisions!B68+Decisions!B86+Decisions!B104+Decisions!B122+Decisions!B140 -> 0 | E19: =Decisions!B18+Decisions!B38 -> 0
A20: G | B20: T | C20: 46 | D20: =Decisions!B71+Decisions!B89+Decisions!B107+Decisions!B125+Decisions!B143 -> 0 | E20: =Decisions!B19+Decisions!B39 -> 0
A21: G | B21: L | C21: 45 | D21: =Decisions!B74+Decisions!B92+Decisions!B110+Decisions!B128+Decisions!B146 -> 0 | E21: =Decisions!B20+Decisions!B40 -> 0
A22: G | B22: L | C22: 46 | D22: =Decisions!B77+Decisions!B95+Decisions!B113+Decisions!B131+Decisions!B149 -> 0 | E22: =Decisions!B21+Decisions!B41 -> 0
A24: Demand satisfaction: sum_p S_{c,i,w_c,p} >= d_{c,i}
A25: c | B25: i | C25: w_c | D25: LHS (sum S) | E25: RHS (d_{c,i})
A26: Orange | B26: P | C26: =Demand!$D$3 -> 45 | D26: 0 | E26: =Demand!$C$3 -> 60000
A27: Orange | B27: T | C27: =Demand!$D$4 -> 45 | D27: 0 | E27: =Demand!$C$4 -> 20000
A28: Orange | B28: L | C28: =Demand!$D$5 -> 45 | D28: 0 | E28: =Demand!$C$5 -> 18000
A29: Enterprise | B29: P | C29: =Demand!$D$6 -> 45 | D29: 0 | E29: =Demand!$C$6 -> 10000
A30: Enterprise | B30: T | C30: =Demand!$D$7 -> 45 | D30: 0 | E30: =Demand!$C$7 -> 5000
A31: Enterprise | B31: L | C31: =Demand!$D$8 -> 45 | D31: 0 | E31: =Demand!$C$8 -> 30000
A32: Amazon | B32: P | C32: =Demand!$D$9 -> 46 | D32: 0 | E32: =Demand!$C$9 -> 80000
A33: Amazon | B33: T | C33: =Demand!$D$10 -> 46 | D33: 0 | E33: =Demand!$C$10 -> 40000
A34: Amazon | B34: L | C34: =Demand!$D$11 -> 46 | D34: 0 | E34: =Demand!$C$11 -> 25000
A35: BestBuy | B35: P | C35: =Demand!$D$12 -> 46 | D35: 0 | E35: =Demand!$C$12 -> 50000
A36: BestBuy | B36: T | C36: =Demand!$D$13 -> 46 | D36: 0 | E36: =Demand!$C$13 -> 30000
A37: BestBuy | B37: L | C37: =Demand!$D$14 -> 46 | D37: 0 | E37: =Demand!$C$14 -> 15000
A38: Target | B38: P | C38: =Demand!$D$15 -> 46 | D38: 0 | E38: =Demand!$C$15 -> 35000
A39: Target | B39: T | C39: =Demand!$D$16 -> 46 | D39: 0 | E39: =Demand!$C$16 -> 25000
A40: Target | B40: L | C40: =Demand!$D$17 -> 46 | D40: 0 | E40: =Demand!$C$17 -> 10000
A42: Capacity-window (regular): sum_i r_i X_{p,i,w} - (W^E Cap - W^S Cap) Y_{p,w} <= W^S Cap
A43: p | B43: w | C43: LHS | D43: RHS
...

Sheet Objective
A1: Objective components
A2: Regular production cost | B2: OT cost | C2: Shipping cost | D2: Penalty cost | E2: Total Z
A3: 0 | B3: 0 | C3: 0 | D3: 0 | E3: =SUM(A3:D3) -> 0

Sheet Decisions_struct
A1: block | B1: =Objective!E3 -> 0 | C1: p_name | D1: i | E1: Decision var count | F1: =ROWS(X_range)+ROWS(XOT_range)+ROWS(S_range)+ROWS(Y_range)+ROWS(YPT_range)+ROWS(E_range) -> 270 | G1: value | H1: type_hint
A2: E | B2: K | C2: Kaohsiung (TW) | E2: 45 | G2: 0 | H2: int
A3: E | B3: K | C3: Kaohsiung (TW) | E3: 46 | G3: 0 | H3: int
A4: E | B4: C | C4: Chennai (IN) | E4: 45 | G4: 0 | H4: int
A5: E | B5: C | C5: Chennai (IN) | E5: 46 | G5: 0 | H5: int
A6: E | B6: G | C6: Guadalajara (MX) | E6: 45 | G6: 0 | H6: int
A7: E | B7: G | C7: Guadalajara (MX) | E7: 46 | G7: 0 | H7: int
A8: S | B8: K | C8: Kaohsiung (TW) | D8: P | E8: 45 | F8: Orange | G8: 0 | H8: int
A9: S | B9: C | C9: Chennai (IN) | D9: P | E9: 45 | F9: Orange | G9: 0 | H9: int
A10: S | B10: G | C10: Guadalajara (MX) | D10: P | E10: 45 | F10: Orange | G10: 0 | H10: int
A11: S | B11: K | C11: Kaohsiung (TW) | D11: P | E11: 45 | F11: Orange | G11: 0 | H11: int
A12: S | B12: C | C12: Chennai (IN) | D12: P | E12: 45 | F12: Orange | G12: 0 | H12: int
A13: S | B13: G | C13: Guadalajara (MX) | D13: P | E13: 45 | F13: Orange | G13: 0 | H13: int
A14: S | B14: K | C14: Kaohsiung (TW) | D14: P | E14: 45 | F14: Orange | G14: 0 | H14: int
A15: S | B15: C | C15: Chennai (IN) | D15: P | E15: 45 | F15: Orange | G15: 0 | H15: int
A16: S | B16: G | C16: Guadalajara (MX) | D16: P | E16: 45 | F16: Orange | G16: 0 | H16: int
A17: S | B17: K | C17: Kaohsiung (TW) | D17: T | E17: 45 | F17: Orange | G17: 0 | H17: int
A18: S | B18: C | C18: Chennai (IN) | D18: T | E18: 45 | F18: Orange | G18: 0 | H18: int
A19: S | B19: G | C19: Guadalajara (MX) | D19: T | E19: 45 | F19: Orange | G19: 0 | H19: int
... A142: S | B142: G | C142: Guadalajara (MX) | D142: L | E142: 46 | F142: Target | G142: 0 | H142: int
A143: X | B143: K | C143: Kaohsiung (TW) | D143: P | E143: 45 | G143: 0 | H143: int
A144: X | B144: K | C144: Kaohsiung (TW) | D144: P | E144: 46 | G144: 0 | H144: int
A145: X | B145: K | C145: Kaohsiung (TW) | D145: T | E145: 45 | G145: 0 | H145: int
A146: X | B146: K | C146: Kaohsiung (TW) | D146: T | E146: 46 | G146: 0 | H146: int
A147: X | B147: K | C147: Kaohsiung (TW) | D147: L | E147: 45 | G147: 0 | H147: int
A148: X | B148: K | C148: Kaohsiung (TW) | D148: L | E148: 46 | G148: 0 | H148: int
A149: X | B149: C | C149: Chennai (IN) | D149: P | E149: 45 | G149: 0 | H149: int
A150: X | B150: C | C150: Chennai (IN) | D150: P | E150: 46 | G150: 0 | H150: int
A151: X | B151: C | C151: Chennai (IN) | D151: T | E151: 45 | G151: 0 | H151: int
A152: X | B152: C | C152: Chennai (IN) | D152: T | E152: 46 | G152: 0 | H152: int
A153: X | B153: C | C153: Chennai (IN) | D153: L | E153: 45 | G153: 0 | H153: int
A154: X | B154: C | C154: Chennai (IN) | D154: L | E154: 46 | G154: 0 | H154: int
... A236: XOT | B236: K | C236: Kaohsiung (TW) | D236: T | E236: 46 | G236: 0 | H236: int
A237: XOT | B237: K | C237: Kaohsiung (TW) | D237: L | E237: 45 | G237: 0 | H237: int | L237: Total Z
A238: XOT | B238: K | C238: Kaohsiung (TW) | D238: L | E238: 46 | G238: 0 | H238: int
A239: XOT | B239: C | C239: Chennai (IN) | D239: P | E239: 45 | G239: 0 | H239: int
A240: XOT | B240: C | C240: Chennai (IN) | D240: P | E240: 46 | G240: 0 | H240: int
A241: XOT | B241: C | C241: Chennai (IN) | D241: T | E241: 45 | G241: 0 | H241: int
A242: XOT | B242: C | C242: Chennai (IN) | D242: T | E242: 46 | G242: 0 | H242: int
A243: XOT | B243: C | C243: Chennai (IN) | D243: L | E243: 45 | G243: 0 | H243: int
...

Sheet NamedRanges
A1: Name | B1: Sheet | C1: Top-left | D1: Bottom-right
A2: X_range | B2: Decisions_struct | C2: $G$2 | D2: $G$55
A3: XOT_range | B3: Decisions_struct | C3: $G$56 | D3: $G$109
A4: Y_range | B4: Decisions_struct | C4: $G$110 | D4: $G$127
A5: S_range | B5: Decisions_struct | C5: $G$128 | D5: $G$397
A6: YPT_range | B6: Decisions_struct | C6: $G$398 | D6: $G$400
A7: Z_range | B7: Objective | C7: E3 | D7: E3

Sheet Constraints_flat
A1: Type | B1: p_code | C1: p_name | D1: i | E1: w | F1: c | G1: LHS | H1: RHS | I1: Relation
A2: Flow | B2: K | C2: Kaohsiung (TW) | D2: P | E2: 45 | G2: =SUMIFS(Decisions_struct!$G:$G,Decisions_struct!$A:$A,"S",Decisions_struct!$B:$B,"K",Decisions_struct!$D:$D,"P",Decisions_struct!$E:$E,45) -> 0 | H2: =SUMIFS(Decisions_struct!$G:$G,Decisions_struct!$A:$A,"X",Decisions_struct!$B:$B,"K",Decisions_struct!$D:$D,"P",Decisions_struct!$E:$E,45)+SUMIFS(Decisions_struct!$G:$G,Decisions_struct!$A:$A,"XOT",Decisions_struct!$B:$B,"K",Decisions_struct!$D:$D,"P",Decisions_struct!$E:$E,45) -> 0 | I2: =N(G2) -> 0 | J2: =N(H2) -> 0
A3: Flow | B3: K | C3: Kaohsiung (TW) | D3: P | E3: 46 | G3: =SUMIFS(Decisions_struct!$G:$G,Decisions_struct!$A:$A,"S",Decisions_struct!$B:$B,"K",Decisions_struct!$D:$D,"P",Decisions_struct!$E:$E,46) -> 0 | H3: =SUMIFS(Decisions_struct!$G:$G,Decisions_struct!$A:$A,"X",Decisions_struct!$B:$B,"K",Decisions_struct!$D:$D,"P",Decisions_struct!$E:$E,46)+SUMIFS(Decisions_struct!$G:$G,Decisions_struct!$A:$A,"XOT",Decisions_struct!$B:$B,"K",Decisions_struct!$D:$D,"P",Decisions_struct!$E:$E,46) -> 0 | I3: =N(G3) -> 0 | J3: =N(H3) -> 0
A4: Flow | B4: K | C4: Kaohsiung (TW) | D4: T | E4: 45 | G4: =SUMIFS(Decisions_struct!$G:$G,Decisions_struct!$A:$A,"S",Decisions_struct!$B:$B,"K",Decisions_struct!$D:$D,"T",Decisions_struct!$E:$E,45) -> 0 | H4: =SUMIFS(Decisions_struct!$G:$G,Decisions_struct!$A:$A,"X",Decisions_struct!$B:$B,"K",Decisions_struct!$D:$D,"T",Decisions_struct!$E:$E,45)+SUMIFS(Decisions_struct!$G:$G,Decisions_struct!$A:$A,"XOT",Decisions_struct!$B:$B,"K",Decisions_struct!$D:$D,"T",Decisions_struct!$E:$E,45) -> 0 | I4: =N(G4) -> 0 | J4: =N(H4) -> 0
A5: Flow | B5: K | C5: Kaohsiung (TW) | D5: T | E5: 46 | G5: =SUMIFS(Decisions_struct!$G:$G,Decisions_struct!$A:$A,"S",Decisions_struct!$B:$B,"K",Decisions_struct!$D:$D,"T",Decisions_struct!$E:$E,46) -> 0 | H5: =SUMIFS(Decisions_struct!$G:$G,Decisions_struct!$A:$A,"X",Decisions_struct!$B:$B,"K",Decisions_struct!$D:$D,"T",Decisions_struct!$E:$E,46)+SUMIFS(Decisions_struct!$G:$G,Decisions_struct!$A:$A,"XOT",Decisions_struct!$B:$B,"K",Decisions_struct!$D:$D,"T",Decisions_struct!$E:$E,46) -> 0 | I5: =N(G5) -> 0 | J5: =N(H5) -> 0
A6: Flow | B6: K | C6: Kaohsiung (TW) | D6: L | E6: 45 | G6: =SUMIFS(Decisions_struct!$G:$G,Decisions_struct!$A:$A,"S",Decisions_struct!$B:$B,"K",Decisions_struct!$D:$D,"L",Decisions_struct!$E:$E,45) -> 0 | H6: =SUMIFS(Decisions_struct!$G:$G,Decisions_struct!$A:$A,"X",Decisions_struct!$B:$B,"K",Decisions_struct!$D:$D,"L",Decisions_struct!$E:$E,45)+SUMIFS(Decisions_struct!$G:$G,Decisions_struct!$A:$A,"XOT",Decisions_struct!$B:$B,"K",Decisions_struct!$D:$D,"L",Decisions_struct!$E:$E,45) -> 0 | I6: =N(G6) -> 0 | J6: =N(H6) -> 0
A7: Flow | B7: K | C7: Kaohsiung (TW) | D7: L | E7: 46 | G7: =SUMIFS(Decisions_struct!$G:$G,Decisions_struct!$A:$A,"S",Decisions_struct!$B:$B,"K",Decisions_struct!$D:$D,"L",Decisions_struct!$E:$E,46) -> 0 | H7: =SUMIFS(Decisions_struct!$G:$G,Decisions_struct!$A:$A,"X",Decisions_struct!$B:$B,"K",Decisions_struct!$D:$D,"L",Decisions_struct!$E:$E,46)+SUMIFS(Decisions_struct!$G:$G,Decisions_struct!$A:$A,"XOT",Decisions_struct!$B:$B,"K",Decisions_struct!$D:$D,"L",Decisions_struct!$E:$E,46) -> 0 | I7: =N(G7) -> 0 | J7: =N(H7) -> 0
A8: Flow | B8: C | C8: Chennai (IN) | D8: P | E8: 45 | G8: =SUMIFS(Decisions_struct!$G:$G,Decisions_struct!$A:$A,"S",Decisions_struct!$B:$B,"C",Decisions_struct!$D:$D,"P",Decisions_struct!$E:$E,45) -> 0 | H8: =SUMIFS(Decisions_struct!$G:$G,Decisions_struct!$A:$A,"X",Decisions_struct!$B:$B,"C",Decisions_struct!$D:$D,"P",Decisions_struct!$E:$E,45)+SUMIFS(Decisions_struct!$G:$G,Decisions_struct!$A:$A,"XOT",Decisions_struct!$B:$B,"C",Decisions_struct!$D:$D,"P",Decisions_struct!$E:$E,45) -> 0 | I8: =N(G8) -> 0 | J8: =N(H8) -> 0
A9: Flow | B9: C | C9: Chennai (IN) | D9: P | E9: 46 | G9: =SUMIFS(Decisions_struct!$G:$G,Decisions_struct!$A:$A,"S",Decisions_struct!$B:$B,"C",Decisions_struct!$D:$D,"P",Decisions_struct!$E:$E,46) -> 0 | H9: =SUMIFS(Decisions_struct!$G:$G,Decisions_struct!$A:$A,"X",Decisions_struct!$B:$B,"C",Decisions_struct!$D:$D,"P",Decisions_struct!$E:$E,46)+SUMIFS(Decisions_struct!$G:$G,Decisions_struct!$A:$A,"XOT",Decisions_struct!$B:$B,"C",Decisions_struct!$D:$D,"P",Decisions_struct!$E:$E,46) -> 0 | I9: =N(G9) -> 0 | J9: =N(H9) -> 0
A10: Flow | B10: C | C10: Chennai (IN) | D10: T | E10: 45 | G10: =SUMIFS(Decisions_struct!$G:$G,Decisions_struct!$A:$A,"S",Decisions_struct!$B:$B,"C",Decisions_struct!$D:$D,"T",Decisions_struct!$E:$E,45) -> 0 | H10: =SUMIFS(Decisions_struct!$G:$G,Decisions_struct!$A:$A,"X",Decisions_struct!$B:$B,"C",Decisions_struct!$D:$D,"T",Decisions_struct!$E:$E,45)+SUMIFS(Decisions_struct!$G:$G,Decisions_struct!$A:$A,"XOT",Decisions_struct!$B:$B,"C",Decisions_struct!$D:$D,"T",Decisions_struct!$E:$E,45) -> 0 | I10: =N(G10) -> 0 | J10: =N(H10) -> 0
A11: Flow | B11: C | C11: Chennai (IN) | D11: T | E11: 46 | G11: =SUMIFS(Decisions_struct!$G:$G,Decisions_struct!$A:$A,"S",Decisions_struct!$B:$B,"C",Decisions_struct!$D:$D,"T",Decisions_struct!$E:$E,46) -> 0 | H11: =SUMIFS(Decisions_struct!$G:$G,Decisions_struct!$A:$A,"X",Decisions_struct!$B:$B,"C",Decisions_struct!$D:$D,"T",Decisions_struct!$E:$E,46)+SUMIFS(Decisions_struct!$G:$G,Decisions_struct!$A:$A,"XOT",Decisions_struct!$B:$B,"C",Decisions_struct!$D:$D,"T",Decisions_struct!$E:$E,46) -> 0 | I11: =N(G11) -> 0 | J11: =N(H11) -> 0
A12: Flow | B12: C | C12: Chennai (IN) | D12: L | E12: 45 | G12: =SUMIFS(Decisions_struct!$G:$G,Decisions_struct!$A:$A,"S",Decisions_struct!$B:$B,"C",Decisions_struct!$D:$D,"L",Decisions_struct!$E:$E,45) -> 0 | H12: =SUMIFS(Decisions_struct!$G:$G,Decisions_struct!$A:$A,"X",Decisions_struct!$B:$B,"C",Decisions_struct!$D:$D,"L",Decisions_struct!$E:$E,45)+SUMIFS(Decisions_struct!$G:$G,Decisions_struct!$A:$A,"XOT",Decisions_struct!$B:$B,"C",Decisions_struct!$D:$D,"L",Decisions_struct!$E:$E,45) -> 0 | I12: =N(G12) -> 0 | J12: =N(H12) -> 0
A13: Flow | B13: C | C13: Chennai (IN) | D13: L | E13: 46 | G13: =SUMIFS(Decisions_struct!$G:$G,Decisions_struct!$A:$A,"S",Decisions_struct!$B:$B,"C",Decisions_struct!$D:$D,"L",Decisions_struct!$E:$E,46) -> 0 | H13: =SUMIFS(Decisions_struct!$G:$G,Decisions_struct!$A:$A,"X",Decisions_struct!$B:$B,"C",Decisions_struct!$D:$D,"L",Decisions_struct!$E:$E,46)+SUMIFS(Decisions_struct!$G:$G,Decisions_struct!$A:$A,"XOT",Decisions_struct!$B:$B,"C",Decisions_struct!$D:$D,"L",Decisions_struct!$E:$E,46) -> 0 | I13: =N(G13) -> 0 | J13: =N(H13) -> 0
A14: Flow | B14: G | C14: Guadalajara (MX) | D14: P | E14: 45 | G14: =SUMIFS(Decisions_struct!$G:$G,Decisions_struct!$A:$A,"S",Decisions_struct!$B:$B,"G",Decisions_struct!$D:$D,"P",Decisions_struct!$E:$E,45) -> 0 | H14: =SUMIFS(Decisions_struct!$G:$G,Decisions_struct!$A:$A,"X",Decisions_struct!$B:$B,"G",Decisions_struct!$D:$D,"P",Decisions_struct!$E:$E,45)+SUMIFS(Decisions_struct!$G:$G,Decisions_struct!$A:$A,"XOT",Decisions_struct!$B:$B,"G",Decisions_struct!$D:$D,"P",Decisions_struct!$E:$E,45) -> 0 | I14: =N(G14) -> 0 | J14: =N(H14) -> 0
A15: Flow | B15: G | C15: Guadalajara (MX) | D15: P | E15: 46 | G15: =SUMIFS(Decisions_struct!$G:$G,Decisions_struct!$A:$A,"S",Decisions_struct!$B:$B,"G",Decisions_struct!$D:$D,"P",Decisions_struct!$E:$E,46) -> 0 | H15: =SUMIFS(Decisions_struct!$G:$G,Decisions_struct!$A:$A,"X",Decisions_struct!$B:$B,"G",Decisions_struct!$D:$D,"P",Decisions_struct!$E:$E,46)+SUMIFS(Decisions_struct!$G:$G,Decisions_struct!$A:$A,"XOT",Decisions_struct!$B:$B,"G",Decisions_struct!$D:$D,"P",Decisions_struct!$E:$E,46) -> 0 | I15: =N(G15) -> 0 | J15: =N(H15) -> 0
A16: Flow | B16: G | C16: Guadalajara (MX) | D16: T | E16: 45 | G16: =SUMIFS(Decisions_struct!$G:$G,Decisions_struct!$A:$A,"S",Decisions_struct!$B:$B,"G",Decisions_struct!$D:$D,"T",Decisions_struct!$E:$E,45) -> 0 | H16: =SUMIFS(Decisions_struct!$G:$G,Decisions_struct!$A:$A,"X",Decisions_struct!$B:$B,"G",Decisions_struct!$D:$D,"T",Decisions_struct!$E:$E,45)+SUMIFS(Decisions_struct!$G:$G,Decisions_struct!$A:$A,"XOT",Decisions_struct!$B:$B,"G",Decisions_struct!$D:$D,"T",Decisions_struct!$E:$E,45) -> 0 | I16: =N(G16) -> 0 | J16: =N(H16) -> 0
A17: Flow | B17: G | C17: Guadalajara (MX) | D17: T | E17: 46 | G17: =SUMIFS(Decisions_struct!$G:$G,Decisions_struct!$A:$A,"S",Decisions_struct!$B:$B,"G",Decisions_struct!$D:$D,"T",Decisions_struct!$E:$E,46) -> 0 | H17: =SUMIFS(Decisions_struct!$G:$G,Decisions_struct!$A:$A,"X",Decisions_struct!$B:$B,"G",Decisions_struct!$D:$D,"T",Decisions_struct!$E:$E,46)+SUMIFS(Decisions_struct!$G:$G,Decisions_struct!$A:$A,"XOT",Decisions_struct!$B:$B,"G",Decisions_struct!$D:$D,"T",Decisions_struct!$E:$E,46) -> 0 | I17: =N(G17) -> 0 | J17: =N(H17) -> 0
A18: Flow | B18: G | C18: Guadalajara (MX) | D18: L | E18: 45 | G18: =SUMIFS(Decisions_struct!$G:$G,Decisions_struct!$A:$A,"S",Decisions_struct!$B:$B,"G",Decisions_struct!$D:$D,"L",Decisions_struct!$E:$E,45) -> 0 | H18: =SUMIFS(Decisions_struct!$G:$G,Decisions_struct!$A:$A,"X",Decisions_struct!$B:$B,"G",Decisions_struct!$D:$D,"L",Decisions_struct!$E:$E,45)+SUMIFS(Decisions_struct!$G:$G,Decisions_struct!$A:$A,"XOT",Decisions_struct!$B:$B,"G",Decisions_struct!$D:$D,"L",Decisions_struct!$E:$E,45) -> 0 | I18: =N(G18) -> 0 | J18: =N(H18) -> 0
A19: Flow | B19: G | C19: Guadalajara (MX) | D19: L | E19: 46 | G19: =SUMIFS(Decisions_struct!$G:$G,Decisions_struct!$A:$A,"S",Decisions_struct!$B:$B,"G",Decisions_struct!$D:$D,"L",Decisions_struct!$E:$E,46) -> 0 | H19: =SUMIFS(Decisions_struct!$G:$G,Decisions_struct!$A:$A,"X",Decisions_struct!$B:$B,"G",Decisions_struct!$D:$D,"L",Decisions_struct!$E:$E,46)+SUMIFS(Decisions_struct!$G:$G,Decisions_struct!$A:$A,"XOT",Decisions_struct!$B:$B,"G",Decisions_struct!$D:$D,"L",Decisions_struct!$E:$E,46) -> 0 | I19: =N(G19) -> 0 | J19: =N(H19) -> 0
A21: Demand | D21: P | F21: Orange | G21: =SUMIFS(Decisions_struct!$G:$G,Decisions_struct!$A:$A,"S",Decisions_struct!$F:$F,"Orange",Decisions_struct!$D:$D,"P") -> 0 | H21: =Demand!$C$3 -> 60000 | I21: =N(G21) -> 0 | J21: =N(H21) -> 60000
A22: Demand | D22: T | F22: Orange | G22: =SUMIFS(Decisions_struct!$G:$G,Decisions_struct!$A:$A,"S",Decisions_struct!$F:$F,"Orange",Decisions_struct!$D:$D,"T") -> 0 | H22: =Demand!$C$4 -> 20000 | I22: =N(G22) -> 0 | J22: =N(H22) -> 20000
A23: Demand | D23: L | F23: Orange | G23: =SUMIFS(Decisions_struct!$G:$G,Decisions_struct!$A:$A,"S",Decisions_struct!$F:$F,"Orange",Decisions_struct!$D:$D,"L") -> 0 | H23: =Demand!$C$5 -> 18000 | I23: =N(G23) -> 0 | J23: =N(H23) -> 18000
A24: Demand | D24: P | F24: Enterprise | G24: =SUMIFS(Decisions_struct!$G:$G,Decisions_struct!$A:$A,"S",Decisions_struct!$F:$F,"Enterprise",Decisions_struct!$D:$D,"P") -> 0 | H24: =Demand!$C$6 -> 10000 | I24: =N(G24) -> 0 | J24: =N(H24) -> 10000
A25: Demand | D25: T | F25: Enterprise | G25: =SUMIFS(Decisions_struct!$G:$G,Decisions_struct!$A:$A,"S",Decisions_struct!$F:$F,"Enterprise",Decisions_struct!$D:$D,"T") -> 0 | H25: =Demand!$C$7 -> 5000 | I25: =N(G25) -> 0 | J25: =N(H25) -> 5000
A26: Demand | D26: L | F26: Enterprise | G26: =SUMIFS(Decisions_struct!$G:$G,Decisions_struct!$A:$A,"S",Decisions_struct!$F:$F,"Enterprise",Decisions_struct!$D:$D,"L") -> 0 | H26: =Demand!$C$8 -> 30000 | I26: =N(G26) -> 0 | J26: =N(H26) -> 30000
A27: Demand | D27: P | F27: Amazon | G27: =SUMIFS(Decisions_struct!$G:$G,Decisions_struct!$A:$A,"S",Decisions_struct!$F:$F,"Amazon",Decisions_struct!$D:$D,"P") -> 0 | H27: =Demand!$C$9 -> 80000 | I27: =N(G27) -> 0 | J27: =N(H27) -> 80000
A28: Demand | D28: T | F28: Amazon | G28: =SUMIFS(Decisions_struct!$G:$G,Decisions_struct!$A:$A,"S",Decisions_struct!$F:$F,"Amazon",Decisions_struct!$D:$D,"T") -> 0 | H28: =Demand!$C$10 -> 40000 | I28: =N(G28) -> 0 | J28: =N(H28) -> 40000
A29: Demand | D29: L | F29: Amazon | G29: =SUMIFS(Decisions_struct!$G:$G,Decisions_struct!$A:$A,"S",Decisions_struct!$F:$F,"Amazon",Decisions_struct!$D:$D,"L") -> 0 | H29: =Demand!$C$11 -> 25000 | I29: =N(G29) -> 0 | J29: =N(H29) -> 25000
A30: Demand | D30: P | F30: BestBuy | G30: =SUMIFS(Decisions_struct!$G:$G,Decisions_struct!$A:$A,"S",Decisions_struct!$F:$F,"BestBuy",Decisions_struct!$D:$D,"P") -> 0 | H30: =Demand!$C$12 -> 50000 | I30: =N(G30) -> 0 | J30: =N(H30) -> 50000
A31: Demand | D31: T | F31: BestBuy | G31: =SUMIFS(Decisions_struct!$G:$G,Decisions_struct!$A:$A,"S",Decisions_struct!$F:$F,"BestBuy",Decisions_struct!$D:$D,"T") -> 0 | H31: =Demand!$C$13 -> 30000 | I31: =N(G31) -> 0 | J31: =N(H31) -> 30000
A32: Demand | D32: L | F32: BestBuy | G32: =SUMIFS(Decisions_struct!$G:$G,Decisions_struct!$A:$A,"S",Decisions_struct!$F:$F,"BestBuy",Decisions_struct!$D:$D,"L") -> 0 | H32: =Demand!$C$14 -> 15000 | I32: =N(G32) -> 0 | J32: =N(H32) -> 15000
A33: Demand | D33: P | F33: Target | G33: =SUMIFS(Decisions_struct!$G:$G,Decisions_struct!$A:$A,"S",Decisions_struct!$F:$F,"Target",Decisions_struct!$D:$D,"P") -> 0 | H33: =Demand!$C$15 -> 35000 | I33: =N(G33) -> 0 | J33: =N(H33) -> 35000
A34: Demand | D34: T | F34: Target | G34: =SUMIFS(Decisions_struct!$G:$G,Decisions_struct!$A:$A,"S",Decisions_struct!$F:$F,"Target",Decisions_struct!$D:$D,"T") -> 0 | H34: =Demand!$C$16 -> 25000 | I34: =N(G34) -> 0 | J34: =N(H34) -> 25000
A35: Demand | D35: L | F35: Target | G35: =SUMIFS(Decisions_struct!$G:$G,Decisions_struct!$A:$A,"S",Decisions_struct!$F:$F,"Target",Decisions_struct!$D:$D,"L") -> 0 | H35: =Demand!$C$17 -> 10000 | I35: =N(G35) -> 0 | J35: =N(H35) -> 10000
A37: Capacity | B37: K | C37: Kaohsiung (TW) | E37: 45 | G37: =1*(SUMIFS(Decisions_struct!$G:$G,Decisions_struct!$A:$A,"X",Decisions_struct!$B:$B,"K",Decisions_struct!$D:$D,"P",Decisions_struct!$E:$E,45)+SUMIFS(Decisions_struct!$G:$G,Decisions_struct!$A:$A,"XOT",Decisions_struct!$B:$B,"K",Decisions_struct!$D:$D,"P",Decisions_struct!$E:$E,45))+1.5*(SUMIFS(Decisions_struct!$G:$G,Decisions_struct!$A:$A,"X",Decisions_struct!$B:$B,"K",Decisions_struct!$D:$D,"T",Decisions_struct!$E:$E,45)+SUMIFS(Decisions_struct!$G:$G,Decisions_struct!$A:$A,"XOT",Decisions_struct!$B:$B,"K",Decisions_struct!$D:$D,"T",Decisions_struct!$E:$E,45))+2*(SUMIFS(Decisions_struct!$G:$G,Decisions_struct!$A:$A,"X",Decisions_struct!$B:$B,"K",Decisions_struct!$D:$D,"L",Decisions_struct!$E:$E,45)+SUMIFS(Decisions_struct!$G:$G,Decisions_struct!$A:$A,"XOT",Decisions_struct!$B:$B,"K",Decisions_struct!$D:$D,"L",Decisions_struct!$E:$E,45)) -> 0 | H37: =18 -> 18 | I37: =N(G37) -> 0 | J37: =N(H37) -> 18
A38: Capacity | B38: K | C38: Kaohsiung (TW) | E38: 46 | G38: =1*(SUMIFS(Decisions_struct!$G:$G,Decisions_struct!$A:$A,"X",Decisions_struct!$B:$B,"K",Decisions_struct!$D:$D,"P",Decisions_struct!$E:$E,46)+SUMIFS(Decisions_struct!$G:$G,Decisions_struct!$A:$A,"XOT",Decisions_struct!$B:$B,"K",Decisions_struct!$D:$D,"P",Decisions_struct!$E:$E,46))+1.5*(SUMIFS(Decisions_struct!$G:$G,Decisions_struct!$A:$A,"X",Decisions_struct!$B:$B,"K",Decisions_struct!$D:$D,"T",Decisions_struct!$E:$E,46)+SUMIFS(Decisions_struct!$G:$G,Decisions_struct!$A:$A,"XOT",Decisions_struct!$B:$B,"K",Decisions_struct!$D:$D,"T",Decisions_struct!$E:$E,46))+2*(SUMIFS(Decisions_struct!$G:$G,Decisions_struct!$A:$A,"X",Decisions_struct!$B:$B,"K",Decisions_struct!$D:$D,"L",Decisions_struct!$E:$E,46)+SUMIFS(Decisions_struct!$G:$G,Decisions_struct!$A:$A,"XOT",Decisions_struct!$B:$B,"K",Decisions_struct!$D:$D,"L",Decisions_struct!$E:$E,46)) -> 0 | H38: =18 -> 18 | I38: =N(G38) -> 0 | J38: =N(H38) -> 18
A39: Capacity | B39: C | C39: Chennai (IN) | E39: 45 | G39: =1*(SUMIFS(Decisions_struct!$G:$G,Decisions_struct!$A:$A,"X",Decisions_struct!$B:$B,"C",Decisions_struct!$D:$D,"P",Decisions_struct!$E:$E,45)+SUMIFS(Decisions_struct!$G:$G,Decisions_struct!$A:$A,"XOT",Decisions_struct!$B:$B,"C",Decisions_struct!$D:$D,"P",Decisions_struct!$E:$E,45))+1.5*(SUMIFS(Decisions_struct!$G:$G,Decisions_struct!$A:$A,"X",Decisions_struct!$B:$B,"C",Decisions_struct!$D:$D,"T",Decisions_struct!$E:$E,45)+SUMIFS(Decisions_struct!$G:$G,Decisions_struct!$A:$A,"XOT",Decisions_struct!$B:$B,"C",Decisions_struct!$D:$D,"T",Decisions_struct!$E:$E,45))+2*(SUMIFS(Decisions_struct!$G:$G,Decisions_struct!$A:$A,"X",Decisions_struct!$B:$B,"C",Decisions_struct!$D:$D,"L",Decisions_struct!$E:$E,45)+SUMIFS(Decisions_struct!$G:$G,Decisions_struct!$A:$A,"XOT",Decisions_struct!$B:$B,"C",Decisions_struct!$D:$D,"L",Decisions_struct!$E:$E,45)) -> 0 | H39: =20 -> 20 | I39: =N(G39) -> 0 | J39: =N(H39) -> 20
A40: Capacity | B40: C | C40: Chennai (IN) | E40: 46 | G40: =1*(SUMIFS(Decisions_struct!$G:$G,Decisions_struct!$A:$A,"X",Decisions_struct!$B:$B,"C",Decisions_struct!$D:$D,"P",Decisions_struct!$E:$E,46)+SUMIFS(Decisions_struct!$G:$G,Decisions_struct!$A:$A,"XOT",Decisions_struct!$B:$B,"C",Decisions_struct!$D:$D,"P",Decisions_struct!$E:$E,46))+1.5*(SUMIFS(Decisions_struct!$G:$G,Decisions_struct!$A:$A,"X",Decisions_struct!$B:$B,"C",Decisions_struct!$D:$D,"T",Decisions_struct!$E:$E,46)+SUMIFS(Decisions_struct!$G:$G,Decisions_struct!$A:$A,"XOT",Decisions_struct!$B:$B,"C",Decisions_struct!$D:$D,"T",Decisions_struct!$E:$E,46))+2*(SUMIFS(Decisions_struct!$G:$G,Decisions_struct!$A:$A,"X",Decisions_struct!$B:$B,"C",Decisions_struct!$D:$D,"L",Decisions_struct!$E:$E,46)+SUMIFS(Decisions_struct!$G:$G,Decisions_struct!$A:$A,"XOT",Decisions_struct!$B:$B,"C",Decisions_struct!$D:$D,"L",Decisions_struct!$E:$E,46)) -> 0 | H40: =20 -> 20 | I40: =N(G40) -> 0 | J40: =N(H40) -> 20
A41: Capacity | B41: G | C41: Guadalajara (MX) | E41: 45 | G41: =1*(SUMIFS(Decisions_struct!$G:$G,Decisions_struct!$A:$A,"X",Decisions_struct!$B:$B,"G",Decisions_struct!$D:$D,"P",Decisions_struct!$E:$E,45)+SUMIFS(Decisions_struct!$G:$G,Decisions_struct!$A:$A,"XOT",Decisions_struct!$B:$B,"G",Decisions_struct!$D:$D,"P",Decisions_struct!$E:$E,45))+1.5*(SUMIFS(Decisions_struct!$G:$G,Decisions_struct!$A:$A,"X",Decisions_struct!$B:$B,"G",Decisions_struct!$D:$D,"T",Decisions_struct!$E:$E,45)+SUMIFS(Decisions_struct!$G:$G,Decisions_struct!$A:$A,"XOT",Decisions_struct!$B:$B,"G",Decisions_struct!$D:$D,"T",Decisions_struct!$E:$E,45))+2*(SUMIFS(Decisions_struct!$G:$G,Decisions_struct!$A:$A,"X",Decisions_struct!$B:$B,"G",Decisions_struct!$D:$D,"L",Decisions_struct!$E:$E,45)+SUMIFS(Decisions_struct!$G:$G,Decisions_struct!$A:$A,"XOT",Decisions_struct!$B:$B,"G",Decisions_struct!$D:$D,"L",Decisions_struct!$E:$E,45)) -> 0 | H41: =3 -> 3 | I41: =N(G41) -> 0 | J41: =N(H41) -> 3
A42: Capacity | B42: G | C42: Guadalajara (MX) | E42: 46 | G42: =1*(SUMIFS(Decisions_struct!$G:$G,Decisions_struct!$A:$A,"X",Decisions_struct!$B:$B,"G",Decisions_struct!$D:$D,"P",Decisions_struct!$E:$E,46)+SUMIFS(Decisions_struct!$G:$G,Decisions_struct!$A:$A,"XOT",Decisions_struct!$B:$B,"G",Decisions_struct!$D:$D,"P",Decisions_struct!$E:$E,46))+1.5*(SUMIFS(Decisions_struct!$G:$G,Decisions_struct!$A:$A,"X",Decisions_struct!$B:$B,"G",Decisions_struct!$D:$D,"T",Decisions_struct!$E:$E,46)+SUMIFS(Decisions_struct!$G:$G,Decisions_struct!$A:$A,"XOT",Decisions_struct!$B:$B,"G",Decisions_struct!$D:$D,"T",Decisions_struct!$E:$E,46))+2*(SUMIFS(Decisions_struct!$G:$G,Decisions_struct!$A:$A,"X",Decisions_struct!$B:$B,"G",Decisions_struct!$D:$D,"L",Decisions_struct!$E:$E,46)+SUMIFS(Decisions_struct!$G:$G,Decisions_struct!$A:$A,"XOT",Decisions_struct!$B:$B,"G",Decisions_struct!$D:$D,"L",Decisions_struct!$E:$E,46)) -> 0 | H42: =3 -> 3 | I42: =N(G42) -> 0 | J42: =N(H42) -> 3
...

Sheet MODEL_Run
A1: Slim model (variables + objective mirror)
A2: Objective mirror | B2: =Objective!E3 -> 0 | E2: Decision count | F2: =ROWS(X_range)+ROWS(XOT_range)+ROWS(S_range)+ROWS(Y_range)+ROWS(YPT_range)+ROWS(E_range) -> 270
A3: block | B3: p | C3: p_name | D3: i | E3: w | F3: value
A4: E_range
A5: E | B5: K | C5: Kaohsiung (TW) | E5: 45 | F5: 0
A6: E | B6: K | C6: Kaohsiung (TW) | E6: 46 | F6: 0
A7: E | B7: C | C7: Chennai (IN) | E7: 45 | F7: 0
A8: E | B8: C | C8: Chennai (IN) | E8: 46 | F8: 0
A9: E | B9: G | C9: Guadalajara (MX) | E9: 45 | F9: 0
A10: E | B10: G | C10: Guadalajara (MX) | E10: 46 | F10: 0
A12: X_range
A13: X | B13: K | C13: Kaohsiung (TW) | D13: P | E13: 45 | F13: 0
A14: X | B14: K | C14: Kaohsiung (TW) | D14: P | E14: 46 | F14: 0
A15: X | B15: K | C15: Kaohsiung (TW) | D15: T | E15: 45 | F15: 0
A16: X | B16: K | C16: Kaohsiung (TW) | D16: T | E16: 46 | F16: 0
A17: X | B17: K | C17: Kaohsiung (TW) | D17: L | E17: 45 | F17: 0
A18: X | B18: K | C18: Kaohsiung (TW) | D18: L | E18: 46 | F18: 0
A19: X | B19: C | C19: Chennai (IN) | D19: P | E19: 45 | F19: 0
A20: X | B20: C | C20: Chennai (IN) | D20: P | E20: 46 | F20: 0
A21: X | B21: C | C21: Chennai (IN) | D21: T | E21: 45 | F21: 0
A22: X | B22: C | C22: Chennai (IN) | D22: T | E22: 46 | F22: 0
A23: X | B23: C | C23: Chennai (IN) | D23: L | E23: 45 | F23: 0
A24: X | B24: C | C24: Chennai (IN) | D24: L | E24: 46 | F24: 0
... A66: X | B66: G | C66: Guadalajara (MX) | D66: L | E66: 46 | F66: 0
A68: XOT_range
A69: XOT | B69: K | C69: Kaohsiung (TW) | D69: P | E69: 45 | F69: 0
A70: XOT | B70: K | C70: Kaohsiung (TW) | D70: P | E70: 46 | F70: 0
A71: XOT | B71: K | C71: Kaohsiung (TW) | D71: T | E71: 45 | F71: 0
A72: XOT | B72: K | C72: Kaohsiung (TW) | D72: T | E72: 46 | F72: 0
A73: XOT | B73: K | C73: Kaohsiung (TW) | D73: L | E73: 45 | F73: 0
A74: XOT | B74: K | C74: Kaohsiung (TW) | D74: L | E74: 46 | F74: 0
A75: XOT | B75: C | C75: Chennai (IN) | D75: P | E75: 45 | F75: 0
A76: XOT | B76: C | C76: Chennai (IN) | D76: P | E76: 46 | F76: 0
A77: XOT | B77: C | C77: Chennai (IN) | D77: T | E77: 45 | F77: 0
A78: XOT | B78: C | C78: Chennai (IN) | D78: T | E78: 46 | F78: 0
A79: XOT | B79: C | C79: Chennai (IN) | D79: L | E79: 45 | F79: 0
A80: XOT | B80: C | C80: Chennai (IN) | D80: L | E80: 46 | F80: 0
... A122: XOT | B122: G | C122: Guadalajara (MX) | D122: L | E122: 46 | F122: 0
A124: S_range
A125: S | B125: K | C125: Kaohsiung (TW) | D125: P | E125: 45 | F125: 0
...

Sheet MODEL_Constraints
A1: Constraints (use these named ranges in OpenSolver)
A3: Name (LHS) | B3: LHS (value) | C3: Name (RHS) | D3: RHS (value)
A4: Flow_LHS | B4: =Flow_LHS -> 0 | C4: Flow_RHS | D4: =Flow_RHS -> 0
A5: Demand_LHS | B5: =Demand_LHS -> #VALUE! | C5: Demand_RHS | D5: =Demand_RHS -> #VALUE!
A6: Capacity_LHS | B6: =Capacity_LHS -> #VALUE! | C6: Capacity_RHS | D6: =Capacity_RHS -> #VALUE!
A7: Cameras_LHS | B7: =Cameras_LHS -> 0 | C7: Cameras_RHS | D7: =Cameras_RHS -> 455000

Sheet README_OpenSolver
A1: OpenSolver quick start
A3: Objective (min): MODEL_Run!$B$2
A4: Variable Cells (names): X_range,XOT_range,S_range,E_range,Y_range,YPT_range
A5: Type constraints: X_range int; XOT_range int; S_range int; Y_range bin; YPT_range bin (leave E_range continuous)
A6: Linear constraints: Flow_LHS<=Flow_RHS; Demand_LHS=Demand_RHS; Capacity_LHS<=Capacity_RHS; Cameras_LHS<=Cameras_RHS
